<?xml version="1.0"?>

<robot xmlns:xacro="http://www.ros.org/wiki/xacro" name="arduinobot">
    <xacro:property name="PI" value="3.14159"/>
    <xacro:property name="effort" value="30.0"/>
    <xacro:property name="velocity" value="10.0"/>
    <link name="world"/>
    <link name="base_link">
        <visual>
            <!-- originally xyz set to 0 0 0. For all STL need to play with the values to make it centered
             Changes position of the mesh relative to the link-->
            <origin rpy="0 0 0" xyz="-0.5 -0.5 0"/>
        <geometry>
            <mesh filename="package://arduinobot_description/meshes/basement.STL" scale="0.01 0.01 0.01"/>
        </geometry>
        
        </visual>
    </link>
    <joint name="virtual_joint" type="fixed">
        <parent link="world"/>
        <child link="base_link"/>
        <origin rpy="0 0 0" xyz="0 0 0"/>
    </joint>

    <link name="base_plate">
        <visual>
            <origin rpy="0 0 0" xyz=" -0.39 -0.39 -0.56"/>
            <geometry>
                <mesh filename="package://arduinobot_description/meshes/base_plate.STL" scale="0.01 0.01 0.01"/>
            </geometry>
        </visual>
    </link>
    <!-- 
        Unlike the base, this section starts the parts of the robot that can move
        So needs to be revolute and set above the base link
    -->
    <joint name="joint_1" type="revolute">
        <parent link="base_link"/>
        <child link="base_plate"/>
        <axis xyz="0 0 1" />
        <origin rpy="0 0 0" xyz="0 0 0.307"/>
        <!-- Min is -90, max is 90 pi to radians-->
        <limit lower="-${PI/2}" upper="${PI/2}" effort="${effort}" velocity="${velocity}"/>
    </joint>


    <!-- Link for the rest of the bot- above was for base and main rotation-->
     <link name="forward_drive_arm">
        <visual>
            <origin rpy="0 -${PI/2} ${PI/2}" xyz="0.19 0.06 -0.06"/>
            <geometry>
                <mesh filename="package://arduinobot_description/meshes/forward_drive_arm.STL" scale="0.01 0.01 0.01"/>
            </geometry>
        </visual>
     </link>
     <!-- Define the second joint for the bot-->
     <joint name="joint_2" type="revolute">
        <parent link="base_plate" />
        <child link= "forward_drive_arm"/>
        <axis xyz="1 0 0" />
        <origin rpy="0 0 0" xyz="-0.02 0 0.35"/>
        <limit lower="-${PI/2}" upper= "${PI/2}" effort="${effort}" velocity="${velocity}"/>
    </joint>
    <link name="horizontal_arm">
        <visual>
            <origin rpy="${PI/2} 0 ${PI/2}" xyz="-0.03 -0.4 -0.06"/>
            <geometry>
                <mesh filename="package://arduinobot_description/meshes/horizontal_arm.STL" scale="0.01 0.01 0.01"/>
            </geometry>
        </visual>

    </link>
    <joint name="joint_3" type="revolute">
        <parent link="forward_drive_arm"></parent>
        <child link="horizontal_arm"/>
        <axis xyz="1 0 0"/>
        <origin rpy="0 0 0" xyz="0 0 0.8"/>
        <limit lower="-${PI/2}" upper= "${PI/2}" effort="${effort}" velocity="${velocity}"/>
    </joint>
    <!--  claw Support link and Joint and stuff. I drank a two sangria this better work-->
    <link name="claw_arm">
        <visual>
            <origin rpy="0 0 ${PI/2}" xyz="0 -0.05 -0.15"/>
            <geometry>
                <mesh filename="package://arduinobot_description/meshes/claw_support.STL" scale="0.01 0.01 0.01"/>
            </geometry>
        </visual>
    </link>
    <joint name="horizontal_arm_to_claw" type="fixed">
        <parent link="horizontal_arm"></parent>
        <child link="claw_arm"/>
        <origin rpy="0 0 0" xyz="0 0.82 0"/>
    </joint>

    <link name="gripper_right">
        <visual>
            <origin xyz="-0.1 0.5 -0.1" rpy="0 0 -${PI/2}"/>
            <geometry>
                <mesh filename="package://arduinobot_description/meshes/right_finger.STL" scale="0.01 0.01 0.01" />
            </geometry>
        </visual>
    </link>

    <link name="gripper_left">
        <visual>
            <origin xyz="-0.04 0.5 -0.1" rpy="0 0 -${PI/2}"/>
            <geometry>
                <mesh filename="package://arduinobot_description/meshes/left_finger.STL" scale="0.01 0.01 0.01" />
            </geometry>
        </visual>
    </link>
    <joint name="joint_4" type="revolute">
        <parent link="claw_arm"/>
        <child link="gripper_right"/>
        <axis xyz="0 0 1" />
        <origin xyz="-0.04 0.13 -0.1" rpy="0 0 0"/>
        <limit lower="-${PI/2}" upper= "0.0" effort="${effort}" velocity="${velocity}"/>
    </joint>
    <joint name="joint_5" type="revolute">
        <parent link="claw_arm"/>
        <child link="gripper_left"/>
        <axis xyz="0 0 1" />
        <origin xyz="-0.22 0.13 -0.1" rpy="0 0 0"/>
        <mimic joint="joint_4" multiplier="-1" />
        <limit lower="0.0" upper= "${PI/2}" effort="${effort}" velocity="${velocity}"/>
    </joint>
</robot>
